<mujoco model="Dice">

    <body name="object" pos="-0.00 -0.02 0.24" user="1001 0 2003 27 0 0 0.06 0 0">
        <inertial diaginertia="6.48e-05 6.48e-05 6.48e-05" mass="0.0550" pos="0 0 0" />

        
        <geom fromto=" 0.0285 -.0285 -.0285  .0285 .0285 -.0285" pos="0 0 0" rgba="1 1 1 1" size=".0050" type="capsule" />
        <geom fromto="-.0285 -.0285 -.0285 -.0285 .0285 -.0285" pos="0 0 0" rgba="1 1 1 1" size=".0050" type="capsule" />
        <geom fromto=" -.0285 .0285 -.0285  .0285 .0285 -.0285" pos="0 0 0" rgba="1 1 1 1" size=".0050" type="capsule" />
        <geom fromto=" -.0285 -.0285 -.0285  .0285 -.0285 -.0285" pos="0 0 0" rgba="1 1 1 1" size=".0050" type="capsule" />
        <geom fromto=" .0285 -.0285 .0285 .0285 .0285 .0285" pos="0 0 0" rgba="1 1 1 1" size=".0050" type="capsule" />
        <geom fromto="-.0285 -.0285 .0285 -.0285 .0285 .0285" pos="0 0 0" rgba="1 1 1 1" size=".0050" type="capsule" />
        <geom fromto=" -.0285 .0285 .0285  .0285 .0285 .0285" pos="0 0 0" rgba="1 1 1 1" size=".0050" type="capsule" />
        <geom fromto=" -.0285 -.0285 .0285  .0285 -.0285 .0285" pos="0 0 0" rgba="1 1 1 1" size=".0050" type="capsule" />
        <geom fromto=".0285 -.0285 -.0285  .0285 -.0285 .0285" pos="0 0 0" rgba="1 1 1 1" size=".0050" type="capsule" />
        <geom fromto=".0285 .0285 -.0285  .0285 .0285 .0285" pos="0 0 0" rgba="1 1 1 1" size=".0050" type="capsule" />
        <geom fromto="-.0285 .0285 -.0285  -.0285 .0285 .0285" pos="0 0 0" rgba="1 1 1 1" size=".0050" type="capsule" />
        <geom fromto="-.0285 -.0285 -.0285  -.0285 -.0285 .0285" pos="0 0 0" rgba="1 1 1 1" size=".0050" type="capsule" />

        
        <geom material="MatDice" size="0.0334 0.0286 0.0286" type="box" />
        <geom material="MatDice" size="0.0286 0.0334 0.0286" type="box" />
        <geom material="MatDice" size="0.0286 0.0286 0.0334" type="box" />

        <joint axis="1 0 0" damping="0.001" name="OBJTx" pos="0 0 0" range="-.5 .5" type="slide" />
        <joint axis="0 1 0" damping="0.001" name="OBJTy" pos="0 0 0" range="-.5 .5" type="slide" />
        <joint axis="0 0 1" damping="0.001" name="OBJTz" pos="0 0 0" range="-.5 .5" type="slide" />
        <joint axis="1 0 0" damping="0.001" limited="false" name="OBJRx" pos="0 0 0  " />
        <joint axis="0 1 0" damping="0.001" limited="false" name="OBJRy" pos="0 0 0" />
        <joint axis="0 0 1" damping="0.001" limited="false" name="OBJRz" pos="0 0 0" />

        <site group="4" name="object_o" pos="0 0 0" rgba="0.8 0.8 0.8 0.8" size="0.005" type="sphere" />
        <site group="4" name="object_x" pos="0.028 0 0" rgba="0.8 0.2 0.2 0.8" size="0.005" type="sphere" />
        <site group="4" name="object_y" pos="0 .028 0" rgba="0.2 0.8 0.2 0.8" size="0.005" type="sphere" />
        <site group="4" name="object_z" pos="0 0 .028" rgba="0.2 0.2 0.8 0.8" size="0.005" type="sphere" />

        
        <site pos="0 0 .05" rgba="1 0 0 .5" size=".003 .05" type="cylinder" />
        <site euler="0 1.57 0" pos=".05 0 0" rgba="0 1 0 .5" size=".003 .05" type="cylinder" />
        <site euler="1.57 0 0" pos="0 .05 0" rgba="0 0 1 .5" size=".003 .05" type="cylinder" />

    </body>

    <body name="target" pos="0 0.2 0.25">

        <geom conaffinity="0" contype="0" material="MatDice" name="target_dice" rgba="1 1 1 .3" size="0.026 0.026 0.026" type="box" />
        <site name="target_ball" rgba="0.2 0.7 0.2 0.1" size="0.07" type="sphere" />
        <site group="4" name="target_o" pos="0 0 0" rgba="0.8 0.8 0.8 0.8" size="0.005" type="sphere" />
        <site group="4" name="target_x" pos="0.03 0 0" rgba="0.8 0.2 0.2 0.8" size="0.005" type="sphere" />
        <site group="4" name="target_y" pos="0 .03 0" rgba="0.2 0.8 0.2 0.8" size="0.005" type="sphere" />
        <site group="4" name="target_z" pos="0 0 .03" rgba="0.2 0.2 0.8 0.8" size="0.005" type="sphere" />

        
        <site pos="0 0 .05" rgba="1 0 0 .5" size=".003 .05" type="cylinder" />
        <site euler="0 1.57 0" pos=".05 0 0" rgba="0 1 0 .5" size=".003 .05" type="cylinder" />
        <site euler="1.57 0 0" pos="0 .05 0" rgba="0 0 1 .5" size=".003 .05" type="cylinder" />


        <joint axis="1 0 0" damping="0.001" limited="false" name="targetRx" pos="0 0 0" />
        <joint axis="0 1 0" damping="0.001" limited="false" name="targetRy" pos="0 0 0" />
        <joint axis="0 0 1" damping="0.001" limited="false" name="targetRz" pos="0 0 0" />
    </body>

 </mujoco>